
<?xml version="1.0" encoding="utf-8"?>
<!-- This URDF was automatically created by SolidWorks to URDF Exporter! Originally created by Stephen Brawner (brawner@gmail.com) 
     Commit Version: 1.6.0-4-g7f85cfe  Build Version: 1.6.7995.38578
     For more information, please see http://wiki.ros.org/sw_urdf_exporter -->
<robot
  name="assembly.SLDASM">
  <link
    name="base_link">
    <inertial>
      <origin
        xyz="7.2882E-09 -0.031299 0.09321"
        rpy="0 0 0" />
      <mass
        value="20.049" />
      <inertia
        ixx="0.42457"
        ixy="2.2569E-08"
        ixz="5.8481E-08"
        iyy="0.34017"
        iyz="0.040982"
        izz="0.49879" />
    </inertial>
    <visual>
      <origin
        xyz="0 0 0"
        rpy="0 0 0" />
      <geometry>
        <mesh
          filename="package://assembly.SLDASM/meshes/base_link.STL" />
      </geometry>
      <material
        name="">
        <color
          rgba="0.79216 0.81961 0.93333 1" />
      </material>
    </visual>
    <collision>
      <origin
        xyz="0 0 0"
        rpy="0 0 0" />
      <geometry>
        <mesh
          filename="package://assembly.SLDASM/meshes/base_link.STL" />
      </geometry>
    </collision>
  </link>
  <link
    name="link_1">
    <inertial>
      <origin
        xyz="1.56260629435856E-10 0.213075746734315 -7.99086934703873E-16"
        rpy="0 0 0" />
      <mass
        value="14.514675782209" />
      <inertia
        ixx="0.281386811179828"
        ixy="1.26852606370379E-09"
        ixz="1.25783244100844E-09"
        iyy="0.109489938167645"
        iyz="9.2738416835237E-18"
        izz="0.308061815657121" />
    </inertial>
    <visual>
      <origin
        xyz="0 0 0"
        rpy="0 0 0" />
      <geometry>
        <mesh
          filename="package://assembly.SLDASM/meshes/link_1.STL" />
      </geometry>
      <material
        name="">
        <color
          rgba="0.792156862745098 0.819607843137255 0.933333333333333 1" />
      </material>
    </visual>
    <collision>
      <origin
        xyz="0 0 0"
        rpy="0 0 0" />
      <geometry>
        <mesh
          filename="package://assembly.SLDASM/meshes/link_1.STL" />
      </geometry>
    </collision>
  </link>
  <joint
    name="joint_1"
    type="revolute">
    <origin
      xyz="0 0 0.16"
      rpy="1.5708 0 0" />
    <parent
      link="base_link" />
    <child
      link="link_1" />
    <axis
      xyz="0 1 0" />
    <limit
      lower="0"
      upper="3.142"
      effort="300"
      velocity="3" />
  </joint>
  <link
    name="link_2">
    <inertial>
      <origin
        xyz="-5.55111512312578E-17 4.43000651155325E-17 0.687560014270784"
        rpy="0 0 0" />
      <mass
        value="15.4604615363391" />
      <inertia
        ixx="0.715192785956185"
        ixy="-1.50291637094616E-12"
        ixz="1.15828073524133E-16"
        iyy="0.620729162221725"
        iyz="3.15069306048419E-18"
        izz="0.156960670855188" />
    </inertial>
    <visual>
      <origin
        xyz="0 0 0"
        rpy="0 0 0" />
      <geometry>
        <mesh
          filename="package://assembly.SLDASM/meshes/link_2.STL" />
      </geometry>
      <material
        name="">
        <color
          rgba="0.792156862745098 0.819607843137255 0.933333333333333 1" />
      </material>
    </visual>
    <collision>
      <origin
        xyz="0 0 0"
        rpy="0 0 0" />
      <geometry>
        <mesh
          filename="package://assembly.SLDASM/meshes/link_2.STL" />
      </geometry>
    </collision>
  </link>
  <joint
    name="joint_2"
    type="revolute">
    <origin
      xyz="0 -0.16 0"
      rpy="-1.5708 0 0" />
    <parent
      link="link_1" />
    <child
      link="link_2" />
    <axis
      xyz="0 -1 0" />
    <limit
      lower="-1.57"
      upper="1.57"
      effort="200"
      velocity="3" />
  </joint>
  <link
    name="link_3">
    <inertial>
      <origin
        xyz="-0.128715523660642 -0.0099999992916806 1.12508937145013"
        rpy="0 0 0" />
      <mass
        value="12.0600722432213" />
      <inertia
        ixx="0.0809201088050546"
        ixy="1.62581330535914E-10"
        ixz="0.0552828443845697"
        iyy="0.370737759040867"
        iyz="-7.84268267852405E-10"
        izz="0.332715991853029" />
    </inertial>
    <visual>
      <origin
        xyz="0 0 0"
        rpy="0 0 0" />
      <geometry>
        <mesh
          filename="package://assembly.SLDASM/meshes/link_3.STL" />
      </geometry>
      <material
        name="">
        <color
          rgba="0.792156862745098 0.819607843137255 0.933333333333333 1" />
      </material>
    </visual>
    <collision>
      <origin
        xyz="0 0 0"
        rpy="0 0 0" />
      <geometry>
        <mesh
          filename="package://assembly.SLDASM/meshes/link_3.STL" />
      </geometry>
    </collision>
  </link>
  <joint
    name="joint_3"
    type="revolute">
    <origin
      xyz="0 0 0"
      rpy="0 0 0" />
    <parent
      link="link_2" />
    <child
      link="link_3" />
    <axis
      xyz="0 -1 0" />
    <limit
      lower="0"
      upper="3.142"
      effort="200"
      velocity="3" />
  </joint>
  <link
    name="link_4">
    <inertial>
      <origin
        xyz="-0.419469400514689 -0.00999999728996523 1.14240924132159"
        rpy="0 0 0" />
      <mass
        value="1.1764892790594" />
      <inertia
        ixx="0.00619563887513839"
        ixy="1.24588611376437E-09"
        ixz="-0.000242489181464342"
        iyy="0.00672004637995692"
        iyz="1.53351673357302E-10"
        izz="0.00215192353129338" />
    </inertial>
    <visual>
      <origin
        xyz="0 0 0"
        rpy="0 0 0" />
      <geometry>
        <mesh
          filename="package://assembly.SLDASM/meshes/link_4.STL" />
      </geometry>
      <material
        name="">
        <color
          rgba="0.792156862745098 0.819607843137255 0.933333333333333 1" />
      </material>
    </visual>
    <collision>
      <origin
        xyz="0 0 0"
        rpy="0 0 0" />
      <geometry>
        <mesh
          filename="package://assembly.SLDASM/meshes/link_4.STL" />
      </geometry>
    </collision>
  </link>
  <joint
    name="joint_4"
    type="revolute">
    <origin
      xyz="0 0 0"
      rpy="0 0 0" />
    <parent
      link="link_3" />
    <child
      link="link_4" />
    <axis
      xyz="0 1 0" />
    <limit
      lower="0"
      upper="-3.142"
      effort="200"
      velocity="3" />
  </joint>
  <transmission name="link_1_trans">
    <type>transmission_interface/SimpleTransmission</type>
    <joint name="joint_1">
      <hardwareInterface>hardware_interface/PositionJointInterface</hardwareInterface>
    </joint>
    <actuator name="link_1_motor">
      <hardwareInterface>hardware_interface/PositionJointInterface</hardwareInterface>
      <mechanicalReduction>1</mechanicalReduction>
    </actuator>
  </transmission>

  <transmission name="link_2_trans">
    <type>transmission_interface/SimpleTransmission</type>
    <joint name="joint_2">
      <hardwareInterface>hardware_interface/PositionJointInterface</hardwareInterface>
    </joint>
    <actuator name="link_2_motor">
      <hardwareInterface>hardware_interface/PositionJointInterface</hardwareInterface>
      <mechanicalReduction>1</mechanicalReduction>
    </actuator>
  </transmission>

  <transmission name="link_3_trans">
    <type>transmission_interface/SimpleTransmission</type>
    <joint name="joint_3">
      <hardwareInterface>hardware_interface/PositionJointInterface</hardwareInterface>
    </joint>
    <actuator name="link_3_motor">
      <hardwareInterface>hardware_interface/PositionJointInterface</hardwareInterface>
      <mechanicalReduction>1</mechanicalReduction>
    </actuator>
  </transmission>

  <transmission name="link_4_trans">
    <type>transmission_interface/SimpleTransmission</type>
    <joint name="joint_4">
      <hardwareInterface>hardware_interface/PositionJointInterface</hardwareInterface>
    </joint>
    <actuator name="link_4_motor">
      <hardwareInterface>hardware_interface/PositionJointInterface</hardwareInterface>
      <mechanicalReduction>1</mechanicalReduction>
    </actuator>
  </transmission>
  <!-- Link del electroimán -->
  <link name="magnet_link">
    <!-- Inercia aproximada -->
    <inertial>
      <mass value="0.5"/>
      <origin xyz="0 0 0" rpy="0 0 0"/>
      <inertia 
        ixx="0.0001" ixy="0.0" ixz="0.0"
        iyy="0.0001" iyz="0.0"
        izz="0.0001"/>
    </inertial>

    <!-- Geometría visual -->
    <visual>
      <origin xyz="0 0 0" rpy="0 0 0"/>
      <geometry>
        <cylinder radius="0.025" length="0.03"/>
      </geometry>
      <material name="Gray">
        <color rgba="0.3 0.3 0.3 1.0"/>
      </material>
    </visual>

    <!-- Geometría de colisión -->
    <collision>
      <origin xyz="0 0 0" rpy="0 0 0"/>
      <geometry>
        <cylinder radius="0.025" length="0.03"/>
      </geometry>
    </collision>
  </link>

  <!-- Joint fijo que une el imán al link_4 -->
  <joint name="magnet_joint" type="fixed">
    <parent link="link_4"/>
    <child  link="magnet_link"/>
    <!-- Puedes ajustar este origen si ves que el imán no queda centrado -->
    <origin xyz="0 0 0.10" rpy="0 0 0"/>
  </joint>
</robot>
